Workbook
Name Biosciences: 'Dashboard Reference '!$D$61:$D$100
Name Computing: 'Dashboard Reference '!$C$61:$C$100
Name Creati: 'Dashboard Reference '!$E$61:$E$100
Name CreativeArts: 'Dashboard Reference '!$E$61:$E$100
Name Law: 'Dashboard Reference '!$A$61:$A$100
Name Psychology: 'Dashboard Reference '!$B$61:$B$100
Name Slicer_Country: #N/A
Name Slicer_Degree: #N/A
Name Slicer_Region: #N/A

Sheet Dashboard
Z15: Graduate Decision System
Z16: Select degree first, then university
Z17: Select degree:
Z18: Computing
Z19: Select University:
Z20: The University of Cambridge
Z21: Region | AA21: {=IFERROR(INDEX(Model!$C:$C,MATCH(1,(Model!$A:$A=Z20)*(Model!$B:$B=Z18),0)),"Make a selection")} -> East
Z22: Guardian Score | AA22: {=IFERROR(INDEX(Model!$D:$D,MATCH(1,(Model!$A:$A=Z20)*(Model!$B:$B=Z18),0)),"")} -> 100
Z23: 1 Year Salary | AA23: {=IFERROR(INDEX(Model!$J:$J,MATCH(1,(Model!$A:$A=Z20)*(Model!$B:$B=Z18),0)),"")} -> 55500
Z24: 3 Year Salary | AA24: {=IFERROR(INDEX(Model!$K:$K,MATCH(1,(Model!$A:$A=Z20)*(Model!$B:$B=Z18),0)),"")} -> 70400
Z25: 5 Year Salary | AA25: {=IFERROR(INDEX(Model!$L:$L,MATCH(1,(Model!$A:$A=Z20)*(Model!$B:$B=Z18),0)),"")} -> 86100
Z26: Adjusted Cost of Living | AA26: {=IFERROR(INDEX(Model!$P:$P,MATCH(1,(Model!$A:$A=Z20)*(Model!$B:$B=Z18),0)),"")} -> 14197.344
Z27: Predicted ROI | AA27: {=IFERROR(INDEX(Model!$Q:$Q,MATCH(1,(Model!$A:$A=Z20)*(Model!$B:$B=Z18),0)),"")} -> 3.3669893
Z28: Payback Period (years) | AA28: {=IFERROR(INDEX(Model!$R:$R,MATCH(1,(Model!$A:$A=Z20)*(Model!$B:$B=Z18),0)),"")} -> 10.4
Z29: Salary Outpaces Loan Interest? | AA29: {=IFERROR(INDEX(Model!$S:$S,MATCH(1,(Model!$A:$A=Z20)*(Model!$B:$B=Z18),0)),"")} -> Yes

Sheet Model
A1: University | B1: Degree | C1: Region | D1: Guardian Score | E1: Dummy Psychology | F1: Dummy computing | G1: Dummy Bio Sci | H1: Dummy Creative arts and design | I1: Group | J1: 1 Year salary | K1: 3 Year salary | L1: 5 Year salary | M1: Chart | N1: Loan repayment | O1: COL index | P1: Adjusted COL | Q1: predicted ROI | R1: Payback period (in years) | S1: Does the salary rate outpace interest? | T1: Annual growth rate of salary
A2: The University of Cambridge | B2: Law | C2: East | D2: 100 | E2: =IF(B2="Psychology",1,0) -> 0 | F2: =IF(B2="Computing",1,0) -> 0 | G2: =IF(B2="Biosciences",1,0) -> 0 | H2: =IF(B2="Creative arts and design",1,0) -> 0 | I2: Top 20 | J2: 30700 | K2: 65300 | L2: 78500 | N2: 0.09 | O2: =VLOOKUP(C2,'GDHI data'!$A:$E,5,0) -> 103.6 | P2: =13704 * (O2/100) -> 14197.344 | Q2: =((J2*2+K2*2+L2))/((29370+P2*5)) -> 2.695385 | R2: =IFERROR(IF(53000/MAX(0,(L2-29385)*0.09)>30,"The loan will not be paid before being written off",ROUND(53000/MAX(0,(L2-29385)*0.09),1)),"Earnings are below the threshold") -> 12 | S2: =IF(MAX(0,(L2*(1.035^5)-29385)*0.09)>53000*0.065,"Yes","No") -> Yes | T2: =(L2/J2)^(1/4)-1 -> 0.26454072 | AD2: Degree | AE2: Avg CAGR | AF2: Avg 1 YAG | AG2: Avg 5 YAG
A3: University College London | B3: Law | C3: London | D3: 99 | E3: =IF(B3="Psychology",1,0) -> 0 | F3: =IF(B3="Computing",1,0) -> 0 | G3: =IF(B3="Biosciences",1,0) -> 0 | H3: =IF(B3="Creative arts and design",1,0) -> 0 | I3: Top 20 | J3: 33800 | K3: 46700 | L3: 58400 | N3: 0.09 | O3: =VLOOKUP(C3,'GDHI data'!$A:$E,5,0) -> 142.4 | P3: =13704 * (O3/100) -> 19514.496 | Q3: =((J3*2+K3*2+L3))/((29370+P3*5)) -> 1.7283418 | R3: =IFERROR(IF(53000/MAX(0,(L3-29385)*0.09)>30,"The loan will not be paid before being written off",ROUND(53000/MAX(0,(L3-29385)*0.09),1)),"Earnings are below the threshold") -> 20.3 | S3: =IF(MAX(0,(L3*(1.035^5)-29385)*0.09)>53000*0.065,"Yes","No") -> Yes | T3: =(L3/J3)^(1/4)-1 -> 0.14649994 | AD3: Law | AE3: =AVERAGEIF(B:B,"Law",T:T) -> 0.1048083 | AF3: =AVERAGEIF(B:B,"Law",J:J) -> 23527.5 | AG3: =AVERAGEIF(B:B,"Law",L:L) -> 37202.5
A4: The University of Oxford | B4: Law | C4: South East | D4: 97.6 | E4: =IF(B4="Psychology",1,0) -> 0 | F4: =IF(B4="Computing",1,0) -> 0 | G4: =IF(B4="Biosciences",1,0) -> 0 | H4: =IF(B4="Creative arts and design",1,0) -> 0 | I4: Top 20 | J4: 33000 | K4: 54800 | L4: 85800 | N4: 0.09 | O4: =VLOOKUP(C4,'GDHI data'!$A:$E,5,0) -> 113.5 | P4: =13704 * (O4/100) -> 15554.04 | Q4: =((J4*2+K4*2+L4))/((29370+P4*5)) -> 2.4397938 | R4: =IFERROR(IF(53000/MAX(0,(L4-29385)*0.09)>30,"The loan will not be paid before being written off",ROUND(53000/MAX(0,(L4-29385)*0.09),1)),"Earnings are below the threshold") -> 10.4 | S4: =IF(MAX(0,(L4*(1.035^5)-29385)*0.09)>53000*0.065,"Yes","No") -> Yes | T4: =(L4/J4)^(1/4)-1 -> 0.26982343 | AD4: Psychology | AE4: =AVERAGEIF(B:B,"Psychology",T:T) -> 0.079884259 | AF4: =AVERAGEIF(B:B,"Psychology",J:J) -> 21630 | AG4: =AVERAGEIF(B:B,"Psychology",L:L) -> 29727.5
A5: The London School of Economics and Political Science | B5: Law | C5: London | D5: 97.3 | E5: =IF(B5="Psychology",1,0) -> 0 | F5: =IF(B5="Computing",1,0) -> 0 | G5: =IF(B5="Biosciences",1,0) -> 0 | H5: =IF(B5="Creative arts and design",1,0) -> 0 | I5: Top 20 | J5: 31000 | K5: 47800 | L5: 79200 | N5: 0.09 | O5: =VLOOKUP(C5,'GDHI data'!$A:$E,5,0) -> 142.4 | P5: =13704 * (O5/100) -> 19514.496 | Q5: =((J5*2+K5*2+L5))/((29370+P5*5)) -> 1.8654118 | R5: =IFERROR(IF(53000/MAX(0,(L5-29385)*0.09)>30,"The loan will not be paid before being written off",ROUND(53000/MAX(0,(L5-29385)*0.09),1)),"Earnings are below the threshold") -> 11.8 | S5: =IF(MAX(0,(L5*(1.035^5)-29385)*0.09)>53000*0.065,"Yes","No") -> Yes | T5: =(L5/J5)^(1/4)-1 -> 0.26427303 | AD5: Computing | AE5: =AVERAGEIF(B:B,"Computing",T:T) -> 0.090477599 | AF5: =AVERAGEIF(B:B,"Computing",J:J) -> 32032.5 | AG5: =AVERAGEIF(B:B,"Computing",L:L) -> 45850
A6: Solent University | B6: Law | C6: South East | D6: 88.8 | E6: =IF(B6="Psychology",1,0) -> 0 | F6: =IF(B6="Computing",1,0) -> 0 | G6: =IF(B6="Biosciences",1,0) -> 0 | H6: =IF(B6="Creative arts and design",1,0) -> 0 | I6: Top 20 | J6: 23000 | K6: 22300 | L6: 27700 | N6: 0.09 | O6: =VLOOKUP(C6,'GDHI data'!$A:$E,5,0) -> 113.5 | P6: =13704 * (O6/100) -> 15554.04 | Q6: =((J6*2+K6*2+L6))/((29370+P6*5)) -> 1.1041607 | R6: =IFERROR(IF(53000/MAX(0,(L6-29385)*0.09)>30,"The loan will not be paid before being written off",ROUND(53000/MAX(0,(L6-29385)*0.09),1)),"Earnings are below the threshold") -> Earnings are below the threshold | S6: =IF(MAX(0,(L6*(1.035^5)-29385)*0.09)>53000*0.065,"Yes","No") -> No | T6: =(L6/J6)^(1/4)-1 -> 0.047581893 | AD6: Biosciences | AE6: =AVERAGEIF(B:B,"Biosciences",T:T) -> 0.078764003 | AF6: =AVERAGEIF(B:B,"Biosciences",J:J) -> 23805 | AG6: =AVERAGEIF(B:B,"Biosciences",L:L) -> 32380
A7: University of Durham | B7: Law | C7: North East | D7: 85.8 | E7: =IF(B7="Psychology",1,0) -> 0 | F7: =IF(B7="Computing",1,0) -> 0 | G7: =IF(B7="Biosciences",1,0) -> 0 | H7: =IF(B7="Creative arts and design",1,0) -> 0 | I7: Top 20 | J7: 25900 | K7: 47800 | L7: 57500 | N7: 0.09 | O7: =VLOOKUP(C7,'GDHI data'!$A:$E,5,0) -> 80.4 | P7: =13704 * (O7/100) -> 11018.016 | Q7: =((J7*2+K7*2+L7))/((29370+P7*5)) -> 2.4259982 | R7: =IFERROR(IF(53000/MAX(0,(L7-29385)*0.09)>30,"The loan will not be paid before being written off",ROUND(53000/MAX(0,(L7-29385)*0.09),1)),"Earnings are below the threshold") -> 20.9 | S7: =IF(MAX(0,(L7*(1.035^5)-29385)*0.09)>53000*0.065,"Yes","No") -> Yes | T7: =(L7/J7)^(1/4)-1 -> 0.22065243 | AD7: Creative arts and design | AE7: =AVERAGEIF(B:B,"Creative arts and design",T:T) -> 0.056892204 | AF7: =AVERAGEIF(B:B,"Creative arts and design",J:J) -> 20442.5 | AG7: =AVERAGEIF(B:B,"Creative arts and design",L:L) -> 25500
A8: King's College London | B8: Law | C8: London | D8: 85.2 | E8: =IF(B8="Psychology",1,0) -> 0 | F8: =IF(B8="Computing",1,0) -> 0 | G8: =IF(B8="Biosciences",1,0) -> 0 | H8: =IF(B8="Creative arts and design",1,0) -> 0 | I8: Top 20 | J8: 28300 | K8: 44500 | L8: 71200 | N8: 0.09 | O8: =VLOOKUP(C8,'GDHI data'!$A:$E,5,0) -> 142.4 | P8: =13704 * (O8/100) -> 19514.496 | Q8: =((J8*2+K8*2+L8))/((29370+P8*5)) -> 1.7078601 | R8: =IFERROR(IF(53000/MAX(0,(L8-29385)*0.09)>30,"The loan will not be paid before being written off",ROUND(53000/MAX(0,(L8-29385)*0.09),1)),"Earnings are below the threshold") -> 14.1 | S8: =IF(MAX(0,(L8*(1.035^5)-29385)*0.09)>53000*0.065,"Yes","No") -> Yes | T8: =(L8/J8)^(1/4)-1 -> 0.25942813
A9: The University of Glasgow | B9: Law | C9: Scotland | D9: 84.2 | E9: =IF(B9="Psychology",1,0) -> 0 | F9: =IF(B9="Computing",1,0) -> 0 | G9: =IF(B9="Biosciences",1,0) -> 0 | H9: =IF(B9="Creative arts and design",1,0) -> 0 | I9: Top 20 | J9: 23000 | K9: 29200 | L9: 40500 | N9: 0.09 | O9: =VLOOKUP(C9,'GDHI data'!$A:$E,5,0) -> 92.2 | P9: =13704 * (O9/100) -> 12635.088 | Q9: =((J9*2+K9*2+L9))/((29370+P9*5)) -> 1.5657173 | R9: =IFERROR(IF(53000/MAX(0,(L9-29385)*0.09)>30,"The loan will not be paid before being written off",ROUND(53000/MAX(0,(L9-29385)*0.09),1)),"Earnings are below the threshold") -> The loan will not be paid before being written off | S9: =IF(MAX(0,(L9*(1.035^5)-29385)*0.09)>53000*0.065,"Yes","No") -> No | T9: =(L9/J9)^(1/4)-1 -> 0.15194514
A10: Leeds Trinity University | B10: Law | C10: Yorkshire and The Humber | D10: 80.6 | E10: =IF(B10="Psychology",1,0) -> 0 | F10: =IF(B10="Computing",1,0) -> 0 | G10: =IF(B10="Biosciences",1,0) -> 0 | H10: =IF(B10="Creative arts and design",1,0) -> 0 | I10: Top 20 | J10: 23000 | K10: 23000 | L10: 23000 | N10: 0.09 | O10: =VLOOKUP(C10,'GDHI data'!$A:$E,5,0) -> 84.7 | P10: =13704 * (O10/100) -> 11607.288 | Q10: =((J10*2+K10*2+L10))/((29370+P10*5)) -> 1.3156925 | R10: =IFERROR(IF(53000/MAX(0,(L10-29385)*0.09)>30,"The loan will not be paid before being written off",ROUND(53000/MAX(0,(L10-29385)*0.09),1)),"Earnings are below the threshold") -> Earnings are below the threshold | S10: =IF(MAX(0,(L10*(1.035^5)-29385)*0.09)>53000*0.065,"Yes","No") -> No | T10: =(L10/J10)^(1/4)-1 -> 0
A11: The University of Edinburgh | B11: Law | C11: Scotland | D11: 79.8 | E11: =IF(B11="Psychology",1,0) -> 0 | F11: =IF(B11="Computing",1,0) -> 0 | G11: =IF(B11="Biosciences",1,0) -> 0 | H11: =IF(B11="Creative arts and design",1,0) -> 0 | I11: Top 20 | J11: 24800 | K11: 32500 | L11: 43100 | N11: 0.09 | O11: =VLOOKUP(C11,'GDHI data'!$A:$E,5,0) -> 92.2 | P11: =13704 * (O11/100) -> 12635.088 | Q11: =((J11*2+K11*2+L11))/((29370+P11*5)) -> 1.7040278 | R11: =IFERROR(IF(53000/MAX(0,(L11-29385)*0.09)>30,"The loan will not be paid before being written off",ROUND(53000/MAX(0,(L11-29385)*0.09),1)),"Earnings are below the threshold") -> The loan will not be paid before being written off | S11: =IF(MAX(0,(L11*(1.035^5)-29385)*0.09)>53000*0.065,"Yes","No") -> No | T11: =(L11/J11)^(1/4)-1 -> 0.14817053
A12: The University of Warwick | B12: Law | C12: West Midlands | D12: 77.8 | E12: =IF(B12="Psychology",1,0) -> 0 | F12: =IF(B12="Computing",1,0) -> 0 | G12: =IF(B12="Biosciences",1,0) -> 0 | H12: =IF(B12="Creative arts and design",1,0) -> 0 | I12: Top 20 | J12: 27400 | K12: 35400 | L12: 50400 | N12: 0.09 | O12: =VLOOKUP(C12,'GDHI data'!$A:$E,5,0) -> 85.1 | P12: =13704 * (O12/100) -> 11662.104 | Q12: =((J12*2+K12*2+L12))/((29370+P12*5)) -> 2.0072874 | R12: =IFERROR(IF(53000/MAX(0,(L12-29385)*0.09)>30,"The loan will not be paid before being written off",ROUND(53000/MAX(0,(L12-29385)*0.09),1)),"Earnings are below the threshold") -> 28 | S12: =IF(MAX(0,(L12*(1.035^5)-29385)*0.09)>53000*0.065,"Yes","No") -> No | T12: =(L12/J12)^(1/4)-1 -> 0.16458179
A13: Queen Mary University of London | B13: Law | C13: London | D13: 77.3 | E13: =IF(B13="Psychology",1,0) -> 0 | F13: =IF(B13="Computing",1,0) -> 0 | G13: =IF(B13="Biosciences",1,0) -> 0 | H13: =IF(B13="Creative arts and design",1,0) -> 0 | I13: Top 20 | J13: 25200 | K13: 30700 | L13: 40300 | N13: 0.09 | O13: =VLOOKUP(C13,'GDHI data'!$A:$E,5,0) -> 142.4 | P13: =13704 * (O13/100) -> 19514.496 | Q13: =((J13*2+K13*2+L13))/((29370+P13*5)) -> 1.1981805 | R13: =IFERROR(IF(53000/MAX(0,(L13-29385)*0.09)>30,"The loan will not be paid before being written off",ROUND(53000/MAX(0,(L13-29385)*0.09),1)),"Earnings are below the threshold") -> The loan will not be paid before being written off | S13: =IF(MAX(0,(L13*(1.035^5)-29385)*0.09)>53000*0.065,"Yes","No") -> No | T13: =(L13/J13)^(1/4)-1 -> 0.12454315
A14: University of Gloucestershire | B14: Law | C14: South West | D14: 77.2 | E14: =IF(B14="Psychology",1,0) -> 0 | F14: =IF(B14="Computing",1,0) -> 0 | G14: =IF(B14="Biosciences",1,0) -> 0 | H14: =IF(B14="Creative arts and design",1,0) -> 0 | I14: Top 20 | J14: 23000 | K14: 25900 | L14: 29000 | N14: 0.09 | O14: =VLOOKUP(C14,'GDHI data'!$A:$E,5,0) -> 100.1 | P14: =13704 * (O14/100) -> 13717.704 | Q14: =((J14*2+K14*2+L14))/((29370+P14*5)) -> 1.2944254 | R14: =IFERROR(IF(53000/MAX(0,(L14-29385)*0.09)>30,"The loan will not be paid before being written off",ROUND(53000/MAX(0,(L14-29385)*0.09),1)),"Earnings are below the threshold") -> Earnings are below the threshold | S14: =IF(MAX(0,(L14*(1.035^5)-29385)*0.09)>53000*0.065,"Yes","No") -> No | T14: =(L14/J14)^(1/4)-1 -> 0.059662439
A15: Bangor University | B15: Law | C15: Wales | D15: 76.1 | E15: =IF(B15="Psychology",1,0) -> 0 | F15: =IF(B15="Computing",1,0) -> 0 | G15: =IF(B15="Biosciences",1,0) -> 0 | H15: =IF(B15="Creative arts and design",1,0) -> 0 | I15: Top 20 | J15: 20100 | K15: 21500 | L15: 26300 | N15: 0.09 | O15: =VLOOKUP(C15,'GDHI data'!$A:$E,5,0) -> 81.1 | P15: =13704 * (O15/100) -> 11113.944 | Q15: =((J15*2+K15*2+L15))/((29370+P15*5)) -> 1.2891495 | R15: =IFERROR(IF(53000/MAX(0,(L15-29385)*0.09)>30,"The loan will not be paid before being written off",ROUND(53000/MAX(0,(L15-29385)*0.09),1)),"Earnings are below the threshold") -> Earnings are below the threshold | S15: =IF(MAX(0,(L15*(1.035^5)-29385)*0.09)>53000*0.065,"Yes","No") -> No | T15: =(L15/J15)^(1/4)-1 -> 0.069522493
A16: The University of Cumbria | B16: Law | C16: North West | D16: 75.8 | E16: =IF(B16="Psychology",1,0) -> 0 | F16: =IF(B16="Computing",1,0) -> 0 | G16: =IF(B16="Biosciences",1,0) -> 0 | H16: =IF(B16="Creative arts and design",1,0) -> 0 | I16: Top 20 | J16: 21500 | K16: 23000 | L16: 28500 | N16: 0.09 | O16: =VLOOKUP(C16,'GDHI data'!$A:$E,5,0) -> 86.7 | P16: =13704 * (O16/100) -> 11881.368 | Q16: =((J16*2+K16*2+L16))/((29370+P16*5)) -> 1.3235434 | R16: =IFERROR(IF(53000/MAX(0,(L16-29385)*0.09)>30,"The loan will not be paid before being written off",ROUND(53000/MAX(0,(L16-29385)*0.09),1)),"Earnings are below the threshold") -> Earnings are below the threshold | S16: =IF(MAX(0,(L16*(1.035^5)-29385)*0.09)>53000*0.065,"Yes","No") -> No | T16: =(L16/J16)^(1/4)-1 -> 0.07300464
A17: The University of Aberdeen | B17: Law | C17: Scotland | D17: 74.4 | E17: =IF(B17="Psychology",1,0) -> 0 | F17: =IF(B17="Computing",1,0) -> 0 | G17: =IF(B17="Biosciences",1,0) -> 0 | H17: =IF(B17="Creative arts and design",1,0) -> 0 | I17: Top 20 | J17: 23500 | K17: 29200 | L17: 40500 | N17: 0.09 | O17: =VLOOKUP(C17,'GDHI data'!$A:$E,5,0) -> 92.2 | P17: =13704 * (O17/100) -> 12635.088 | Q17: =((J17*2+K17*2+L17))/((29370+P17*5)) -> 1.5765228 | R17: =IFERROR(IF(53000/MAX(0,(L17-29385)*0.09)>30,"The loan will not be paid before being written off",ROUND(53000/MAX(0,(L17-29385)*0.09),1)),"Earnings are below the threshold") -> The loan will not be paid before being written off | S17: =IF(MAX(0,(L17*(1.035^5)-29385)*0.09)>53000*0.065,"Yes","No") -> No | T17: =(L17/J17)^(1/4)-1 -> 0.14576827
A18: University of Bristol | B18: Law | C18: South West | D18: 74.2 | E18: =IF(B18="Psychology",1,0) -> 0 | F18: =IF(B18="Computing",1,0) -> 0 | G18: =IF(B18="Biosciences",1,0) -> 0 | H18: =IF(B18="Creative arts and design",1,0) -> 0 | I18: Top 20 | J18: 23700 | K18: 38700 | L18: 51800 | N18: 0.09 | O18: =VLOOKUP(C18,'GDHI data'!$A:$E,5,0) -> 100.1 | P18: =13704 * (O18/100) -> 13717.704 | Q18: =((J18*2+K18*2+L18))/((29370+P18*5)) -> 1.8028039 | R18: =IFERROR(IF(53000/MAX(0,(L18-29385)*0.09)>30,"The loan will not be paid before being written off",ROUND(53000/MAX(0,(L18-29385)*0.09),1)),"Earnings are below the threshold") -> 26.3 | S18: =IF(MAX(0,(L18*(1.035^5)-29385)*0.09)>53000*0.065,"Yes","No") -> No | T18: =(L18/J18)^(1/4)-1 -> 0.21589299
A19: University of Southampton | B19: Law | C19: South East | D19: 74.1 | E19: =IF(B19="Psychology",1,0) -> 0 | F19: =IF(B19="Computing",1,0) -> 0 | G19: =IF(B19="Biosciences",1,0) -> 0 | H19: =IF(B19="Creative arts and design",1,0) -> 0 | I19: Top 20 | J19: 24100 | K19: 30700 | L19: 40500 | N19: 0.09 | O19: =VLOOKUP(C19,'GDHI data'!$A:$E,5,0) -> 113.5 | P19: =13704 * (O19/100) -> 15554.04 | Q19: =((J19*2+K19*2+L19))/((29370+P19*5)) -> 1.4009681 | R19: =IFERROR(IF(53000/MAX(0,(L19-29385)*0.09)>30,"The loan will not be paid before being written off",ROUND(53000/MAX(0,(L19-29385)*0.09),1)),"Earnings are below the threshold") -> The loan will not be paid before being written off | S19: =IF(MAX(0,(L19*(1.035^5)-29385)*0.09)>53000*0.065,"Yes","No") -> No | T19: =(L19/J19)^(1/4)-1 -> 0.13856937
... A201: University of Winchester | B201: Creative arts and design | C201: South East | D201: 33.3 | E201: =IF(B201="Psychology",1,0) -> 0 | F201: =IF(B201="Computing",1,0) -> 0 | G201: =IF(B201="Biosciences",1,0) -> 0 | H201: =IF(B201="Creative arts and design",1,0) -> 1 | I201: Bottom 20 | J201: 21500 | K201: 26800 | L201: 30200 | N201: 0.09 | O201: =VLOOKUP(C201,'GDHI data'!$A:$E,5,0) -> 113.5 | P201: =13704 * (O201/100) -> 15554.04 | Q201: =((J201*2+K201*2+L201))/((29370+P201*5)) -> 1.183496 | R201: =IFERROR(IF(53000/MAX(0,(L201-29385)*0.09)>30,"The loan will not be paid before being written off",ROUND(53000/MAX(0,(L201-29385)*0.09),1)),"Earnings are below the threshold") -> The loan will not be paid before being written off | S201: =IF(MAX(0,(L201*(1.035^5)-29385)*0.09)>53000*0.065,"Yes","No") -> No | T201: =(L201/J201)^(1/4)-1 -> 0.088659635

Sheet Lookup table
A1: University | B1: Ranking | C1: Guardian score | D1: Satisfied with teaching | E1: Satisfied with feedback | F1: Student to staff ratio | G1: Spend per student/10 | H1: Average entry tariff | I1: Value added score/10 | J1: Career after 15 months | K1: Continuation | L1: Degree | M1: Bottom or Top 20 | N1: Average Career After 15 Months
A2: Cambridge - Law | B2: 1 | C2: 100 | D2: 93.3 | E2: 65.3 | F2: 14.5 | G2: 10 | H2: 203 | I2: 8 | J2: 98 | K2: 99.1 | L2: Law | M2: Top 20 | N2: =AVERAGE($J$2:$J$21) -> 88.578947
A3: UCL - Law | B3: 2 | C3: 99 | D3: 90.1 | E3: 69.7 | F3: 14.2 | G3: 10 | H3: 197 | I3: 9 | J3: 93 | K3: 100 | L3: Law | M3: Top 20 | N3: =AVERAGE($J$2:$J$21) -> 88.578947
A4: Oxford - Law | B4: 3 | C4: 97.6 | D4: 90.1 | E4: 70.4 | F4: 12.6 | G4: 10 | H4: 205 | I4: 7 | J4: 93 | K4: 98.8 | L4: Law | M4: Top 20 | N4: =AVERAGE($J$2:$J$21) -> 88.578947
A5: London School of Economics - Law | B5: 4 | C5: 97.3 | D5: 90.8 | E5: 78.1 | F5: 13.5 | G5: 10 | H5: 203 | I5: 9 | J5: 90 | K5: 98.9 | L5: Law | M5: Top 20 | N5: =AVERAGE($J$2:$J$21) -> 88.578947
A6: Solent - Law | B6: 5 | C6: 88.8 | D6: 91.1 | E6: 83.3 | G6: 7 | H6: 115 | I6: 10 | J6: 83 | K6: 93.7 | L6: Law | M6: Top 20 | N6: =AVERAGE($J$2:$J$21) -> 88.578947
A7: Durham - Law | B7: 6 | C7: 85.8 | D7: 87.7 | E7: 72 | F7: 16.5 | G7: 7 | H7: 189 | I7: 8 | J7: 91 | K7: 98.9 | L7: Law | M7: Top 20 | N7: =AVERAGE($J$2:$J$21) -> 88.578947
A8: King's College London - Law | B8: 7 | C8: 85.2 | D8: 88.7 | E8: 68.3 | F8: 17.2 | G8: 10 | H8: 196 | I8: 9 | J8: 91 | K8: 93.4 | L8: Law | M8: Top 20 | N8: =AVERAGE($J$2:$J$21) -> 88.578947
A9: Glasgow - Law | B9: 8 | C9: 84.2 | D9: 88.3 | E9: 62.6 | F9: 17.8 | G9: 7 | H9: 223 | I9: 8 | J9: 91 | K9: 95.8 | L9: Law | M9: Top 20 | N9: =AVERAGE($J$2:$J$21) -> 88.578947
A10: Leeds Trinity - Law | B10: 9 | C10: 80.6 | D10: 83.2 | E10: 87.6 | F10: 16.1 | G10: 3 | H10: 118 | I10: 8 | K10: 90.1 | L10: Law | M10: Top 20 | N10: =AVERAGE($J$2:$J$21) -> 88.578947
A11: Edinburgh - Law | B11: 10 | C11: 79.8 | D11: 85.8 | E11: 58.9 | F11: 17.5 | G11: 7 | H11: 220 | I11: 7 | J11: 92 | K11: 96.2 | L11: Law | M11: Top 20 | N11: =AVERAGE($J$2:$J$21) -> 88.578947
A12: Warwick - Law | B12: 11 | C12: 77.8 | D12: 86.4 | E12: 64.7 | F12: 16.6 | G12: 8 | H12: 172 | I12: 6 | J12: 90 | K12: 99.2 | L12: Law | M12: Top 20 | N12: =AVERAGE($J$2:$J$21) -> 88.578947
A13: Queen Mary - Law | B13: 12 | C13: 77.3 | D13: 85.3 | E13: 61.6 | F13: 19.1 | G13: 9 | H13: 173 | I13: 9 | J13: 90 | K13: 96.5 | L13: Law | M13: Top 20 | N13: =AVERAGE($J$2:$J$21) -> 88.578947
A14: Gloucestershire - Law | B14: 13 | C14: 77.2 | D14: 93.9 | E14: 89.8 | F14: 15.9 | G14: 8 | H14: 104 | J14: 85 | K14: 91.3 | L14: Law | M14: Top 20 | N14: =AVERAGE($J$2:$J$21) -> 88.578947
A15: Bangor - Law | B15: 14 | C15: 76.1 | D15: 84 | E15: 78.8 | F15: 22.3 | G15: 3 | H15: 134 | I15: 10 | J15: 85 | K15: 93.2 | L15: Law | M15: Top 20 | N15: =AVERAGE($J$2:$J$21) -> 88.578947
A16: Cumbria - Law | B16: 15 | C16: 75.8 | D16: 92.3 | E16: 91 | H16: 125 | I16: 7 | J16: 73 | K16: 91 | L16: Law | M16: Top 20 | N16: =AVERAGE($J$2:$J$21) -> 88.578947
A17: Aberdeen - Law | B17: 16 | C17: 74.4 | D17: 90.4 | E17: 69.4 | F17: 25.2 | G17: 5 | H17: 204 | I17: 8 | J17: 88 | K17: 95.2 | L17: Law | M17: Top 20 | N17: =AVERAGE($J$2:$J$21) -> 88.578947
A18: Bristol - Law | B18: 17 | C18: 74.2 | D18: 84.1 | E18: 62.2 | F18: 19.3 | G18: 8 | H18: 185 | I18: 6 | J18: 91 | K18: 97.8 | L18: Law | M18: Top 20 | N18: =AVERAGE($J$2:$J$21) -> 88.578947
A19: Southampton - Law | B19: 18 | C19: 74.1 | D19: 86 | E19: 72.8 | F19: 15.4 | G19: 7 | H19: 151 | I19: 6 | J19: 92 | K19: 95.8 | L19: Law | M19: Top 20 | N19: =AVERAGE($J$2:$J$21) -> 88.578947
A20: South Wales - Law | B20: 19 | C20: 73.5 | D20: 90.3 | E20: 87.6 | F20: 27.4 | G20: 6 | H20: 128 | I20: 9 | J20: 80 | K20: 89 | L20: Law | M20: Top 20 | N20: =AVERAGE($J$2:$J$21) -> 88.578947
A21: Lancaster - Law | B21: 20 | C21: 73 | D21: 90.9 | E21: 83.6 | F21: 22.6 | G21: 6 | H21: 153 | I21: 5 | J21: 87 | K21: 95.4 | L21: Law | M21: Top 20 | N21: =AVERAGE($J$2:$J$21) -> 88.578947
A22: East London - Law | B22: 89 | C22: 49.9 | D22: 84.7 | E22: 82.8 | F22: 19.2 | G22: 2 | H22: 106 | I22: 4 | J22: 65 | K22: 87.6 | L22: Law | M22: Bottom 20 | N22: =AVERAGE($J$22:$J$41) -> 76.647059
A23: Oxford Brookes - Law | B23: 90 | C23: 49.5 | D23: 82.7 | E23: 74 | F23: 22 | G23: 2 | H23: 112 | I23: 2 | J23: 80 | K23: 94 | L23: Law | M23: Bottom 20 | N23: =AVERAGE($J$22:$J$41) -> 76.647059
A24: Lincoln - Law | B24: 91 | C24: 49.1 | D24: 85.2 | E24: 67.8 | F24: 22.3 | G24: 3 | H24: 120 | I24: 2 | J24: 83 | K24: 93.7 | L24: Law | M24: Bottom 20 | N24: =AVERAGE($J$22:$J$41) -> 76.647059
A25: Liverpool John Moores - Law | B25: 92 | C25: 48.6 | D25: 88.1 | E25: 77.5 | F25: 25.3 | G25: 3 | H25: 127 | I25: 1 | J25: 83 | K25: 90.8 | L25: Law | M25: Bottom 20 | N25: =AVERAGE($J$22:$J$41) -> 76.647059
A26: Anglia Ruskin - Law | B26: 93 | C26: 48 | D26: 82.7 | E26: 77.9 | F26: 26.2 | H26: 109 | I26: 7 | J26: 69 | K26: 84.2 | L26: Law | M26: Bottom 20 | N26: =AVERAGE($J$22:$J$41) -> 76.647059
A27: Bradford - Law | B27: 94 | C27: 46.8 | D27: 81.9 | E27: 80.6 | F27: 34.2 | G27: 2 | H27: 126 | I27: 7 | J27: 76 | K27: 88.1 | L27: Law | M27: Bottom 20 | N27: =AVERAGE($J$22:$J$41) -> 76.647059
A28: Staffordshire - Law | B28: 95 | C28: 46.7 | D28: 90.1 | E28: 85.5 | F28: 25.6 | G28: 8 | H28: 126 | I28: 5 | J28: 67 | K28: 80.6 | L28: Law | M28: Bottom 20 | N28: =AVERAGE($J$22:$J$41) -> 76.647059
A29: Robert Gordon - Law | B29: 96 | C29: 46.6 | D29: 80.7 | E29: 71.8 | F29: 24.9 | G29: 3 | H29: 158 | I29: 7 | J29: 88 | K29: 81.9 | L29: Law | M29: Bottom 20 | N29: =AVERAGE($J$22:$J$41) -> 76.647059
A30: Brunel - Law | B30: 97 | C30: 45.7 | D30: 72.7 | E30: 60.2 | F30: 18.5 | G30: 8 | H30: 123 | I30: 1 | J30: 83 | K30: 93.6 | L30: Law | M30: Bottom 20 | N30: =AVERAGE($J$22:$J$41) -> 76.647059
A31: Winchester - Law | B31: 98 | C31: 45.6 | D31: 83.6 | E31: 75.8 | F31: 21.3 | G31: 2 | H31: 119 | I31: 4 | J31: 83 | K31: 83.1 | L31: Law | M31: Bottom 20 | N31: =AVERAGE($J$22:$J$41) -> 76.647059
A32: Royal Holloway - Law | B32: 98 | C32: 45.6 | D32: 78.1 | E32: 66.9 | F32: 23.7 | G32: 3 | H32: 138 | I32: 3 | J32: 88 | K32: 89.4 | L32: Law | M32: Bottom 20 | N32: =AVERAGE($J$22:$J$41) -> 76.647059
A33: Roehampton - Law | B33: 100 | C33: 45.4 | D33: 85.3 | E33: 77.9 | F33: 33.3 | G33: 4 | H33: 100 | I33: 4 | J33: 70 | K33: 92.3 | L33: Law | M33: Bottom 20 | N33: =AVERAGE($J$22:$J$41) -> 76.647059
A34: Brighton - Law | B34: 101 | C34: 42.6 | D34: 79.2 | E34: 71.8 | F34: 26.7 | G34: 3 | H34: 107 | I34: 6 | J34: 82 | K34: 85.2 | L34: Law | M34: Bottom 20 | N34: =AVERAGE($J$22:$J$41) -> 76.647059
A35: Liverpool Hope - Law | B35: 102 | C35: 42.2 | D35: 75.5 | E35: 77.6 | F35: 22.6 | G35: 1 | H35: 111 | I35: 2 | K35: 88.2 | L35: Law | M35: Bottom 20 | N35: =AVERAGE($J$22:$J$41) -> 76.647059
A36: Huddersfield - Law | B36: 103 | C36: 42.1 | D36: 78.8 | E36: 80.7 | F36: 26.9 | G36: 5 | H36: 122 | I36: 4 | J36: 72 | K36: 89.1 | L36: Law | M36: Bottom 20 | N36: =AVERAGE($J$22:$J$41) -> 76.647059
A37: Leeds Beckett - Law | B37: 104 | C37: 40 | D37: 88.9 | E37: 83.5 | F37: 23.9 | G37: 4 | H37: 122 | I37: 1 | J37: 74 | K37: 85.7 | L37: Law | M37: Bottom 20 | N37: =AVERAGE($J$22:$J$41) -> 76.647059
A38: Birmingham City - Law | B38: 105 | C38: 38.4 | D38: 81.4 | E38: 69.4 | F38: 27.3 | G38: 4 | H38: 123 | I38: 2 | J38: 72 | K38: 90.9 | L38: Law | M38: Bottom 20 | N38: =AVERAGE($J$22:$J$41) -> 76.647059
A39: West of Scotland - Law | B39: 106 | C39: 37 | D39: 84.6 | E39: 79.1 | F39: 33.9 | G39: 4 | H39: 139 | I39: 9 | K39: 77 | L39: Law | M39: Bottom 20 | N39: =AVERAGE($J$22:$J$41) -> 76.647059
A40: Bolton - Law | B40: 107 | C40: 34.9 | D40: 85.3 | E40: 73.5 | F40: 27.2 | G40: 5 | H40: 103 | K40: 78.1 | L40: Law | M40: Bottom 20 | N40: =AVERAGE($J$22:$J$41) -> 76.647059
...

Sheet GDHI data
A1: Countries and regions of the UK | B1: Population (million) | C1: GDHI per head (£) | D1: Growth in GDHI per head (percentage) | E1: GDHI per head index (UK=100) | F1: Total GDHI (£ million) | G1: Total GDHI growth from 2022 to 2023 (percentage) | H1: Share of UK total GDHI (percentage)
A2: United Kingdom | B2: 68.3 | C2: 24836 | D2: 8.4 | E2: 100 | F2: 1695436 | G2: 9.5 | H2: 100
A3: England | B3: 57.7 | C3: 25425 | D3: 8.5 | E3: 102.4 | F3: 1466758 | G3: 9.6 | H3: 86.5
A4: North East | B4: 2.7 | C4: 19977 | D4: 8.5 | E4: 80.4 | F4: 54165 | G4: 9.6 | H4: 3.2
A5: North West | B5: 7.6 | C5: 21543 | D5: 8.6 | E5: 86.7 | F5: 163730 | G5: 9.8 | H5: 9.7
A6: Yorkshire and The Humber | B6: 5.6 | C6: 21027 | D6: 8.5 | E6: 84.7 | F6: 117626 | G6: 9.6 | H6: 6.9
A7: East Midlands | B7: 5 | C7: 21656 | D7: 8.3 | E7: 87.2 | F7: 108089 | G7: 9.5 | H7: 6.4
A8: West Midlands | B8: 6.1 | C8: 21141 | D8: 8.4 | E8: 85.1 | F8: 128655 | G8: 9.6 | H8: 7.6
A9: East | B9: 6.5 | C9: 25732 | D9: 8.5 | E9: 103.6 | F9: 166455 | G9: 9.7 | H9: 9.8
A10: London | B10: 8.9 | C10: 35361 | D10: 8.6 | E10: 142.4 | F10: 316319 | G10: 9.6 | H10: 18.7
A11: South East | B11: 9.5 | C11: 28187 | D11: 8.1 | E11: 113.5 | F11: 267287 | G11: 9.2 | H11: 15.8
A12: South West | B12: 5.8 | C12: 24854 | D12: 9.3 | E12: 100.1 | F12: 144431 | G12: 10.1 | H12: 8.5
A13: Wales | B13: 3.2 | C13: 20140 | D13: 6.8 | E13: 81.1 | F13: 63730 | G13: 7.9 | H13: 3.8
... A15: Northern Ireland | B15: 1.9 | C15: 20403 | D15: 7.9 | E15: 82.2 | F15: 39181 | G15: 8.5 | H15: 2.3
A111: Source: Numbeo Cost of Living Index (Current, April 2026) — numbeo.com/cost-of-living/rankings_current.jsp | Cities without direct Numbeo data use nearest city or regional average.

Sheet sensitivity analysis
A1: Sensitivity analysis - how does a change in x Guardian score effect predicted salary (based on 5 YAG)
B3: Guardian Score | C3: Law | D3: Psychology | E3: Computing | F3: Biosciences | G3: Design
B4: 30 | C4: ='YAG 5 regression'!$B$17+('YAG 5 regression'!$B$18*B4) -> 27626.562 | D4: ='YAG 5 regression'!$B$17+('YAG 5 regression'!$B$18*B4)+('YAG 5 regression'!$B$19) -> 20253.28 | E4: ='YAG 5 regression'!$B$17+('YAG 5 regression'!$B$18*B4)+('YAG 5 regression'!$B$20) -> 36603.023 | F4: ='YAG 5 regression'!$B$17+('YAG 5 regression'!$B$18*B4)+('YAG 5 regression'!$B$21) -> 21696.704 | G4: ='YAG 5 regression'!$B$17+('YAG 5 regression'!$B$18*B4)+('YAG 5 regression'!$B$22) -> 14756.106
B5: 50 | C5: ='YAG 5 regression'!$B$17+('YAG 5 regression'!$B$18*B5) -> 33397.807 | D5: ='YAG 5 regression'!$B$17+('YAG 5 regression'!$B$18*B5)+('YAG 5 regression'!$B$19) -> 26024.525 | E5: ='YAG 5 regression'!$B$17+('YAG 5 regression'!$B$18*B5)+('YAG 5 regression'!$B$20) -> 42374.268 | F5: ='YAG 5 regression'!$B$17+('YAG 5 regression'!$B$18*B5)+('YAG 5 regression'!$B$21) -> 27467.949 | G5: ='YAG 5 regression'!$B$17+('YAG 5 regression'!$B$18*B5)+('YAG 5 regression'!$B$22) -> 20527.351
B6: 70 | C6: ='YAG 5 regression'!$B$17+('YAG 5 regression'!$B$18*B6) -> 39169.052 | D6: ='YAG 5 regression'!$B$17+('YAG 5 regression'!$B$18*B6)+('YAG 5 regression'!$B$19) -> 31795.77 | E6: ='YAG 5 regression'!$B$17+('YAG 5 regression'!$B$18*B6)+('YAG 5 regression'!$B$20) -> 48145.513 | F6: ='YAG 5 regression'!$B$17+('YAG 5 regression'!$B$18*B6)+('YAG 5 regression'!$B$21) -> 33239.194 | G6: ='YAG 5 regression'!$B$17+('YAG 5 regression'!$B$18*B6)+('YAG 5 regression'!$B$22) -> 26298.596
B7: 90 | C7: ='YAG 5 regression'!$B$17+('YAG 5 regression'!$B$18*B7) -> 44940.297 | D7: ='YAG 5 regression'!$B$17+('YAG 5 regression'!$B$18*B7)+('YAG 5 regression'!$B$19) -> 37567.015 | E7: ='YAG 5 regression'!$B$17+('YAG 5 regression'!$B$18*B7)+('YAG 5 regression'!$B$20) -> 53916.758 | F7: ='YAG 5 regression'!$B$17+('YAG 5 regression'!$B$18*B7)+('YAG 5 regression'!$B$21) -> 39010.439 | G7: ='YAG 5 regression'!$B$17+('YAG 5 regression'!$B$18*B7)+('YAG 5 regression'!$B$22) -> 32069.841
B8: 100 | C8: ='YAG 5 regression'!$B$17+('YAG 5 regression'!$B$18*B8) -> 47825.919 | D8: ='YAG 5 regression'!$B$17+('YAG 5 regression'!$B$18*B8)+('YAG 5 regression'!$B$19) -> 40452.637 | E8: ='YAG 5 regression'!$B$17+('YAG 5 regression'!$B$18*B8)+('YAG 5 regression'!$B$20) -> 56802.38 | F8: ='YAG 5 regression'!$B$17+('YAG 5 regression'!$B$18*B8)+('YAG 5 regression'!$B$21) -> 41896.062 | G8: ='YAG 5 regression'!$B$17+('YAG 5 regression'!$B$18*B8)+('YAG 5 regression'!$B$22) -> 34955.464
B9: Source: Regression coefficients from YAG 5 regression — all variables significant at p<0.05

Sheet YAG 1 regression
A1: YAG 1 Regression — Predicted Salary vs Guardian Score and Degree Dummies
A3: Regression Statistics
A4: Multiple R | B4: 0.72127239
A5: R Square | B5: 0.52023386
A6: Adjusted R Square | B6: 0.50786876
A7: Standard Error | B7: 4690.2992
A8: Observations | B8: 200
A10: ANOVA
B11: df | C11: SS | D11: MS | E11: F | F11: Significance F
A12: Regression | B12: 5 | C12: 4.6277709e+09 | D12: 9.2555418e+08 | E12: 42.072736 | F12: 3.1999463e-29
A13: Residual | B13: 194 | C13: 4.2677878e+09 | D13: 21998906
A14: Total | B14: 199 | C14: 8895558750
B16: Coefficients | C16: Standard Error | D16: t Stat | E16: P-value | F16: Lower 95% | G16: Upper 95% | H16: Lower 95.0% | I16: Upper 95.0%
A17: Intercept | B17: 15455.879 | C17: 1278.2976 | D17: 12.090986 | E17: 1.8946297e-25 | F17: 12934.734 | G17: 17977.024 | H17: 12934.734 | I17: 17977.024
A18: Subject Guardian Score | B18: 127.74584 | C18: 16.478402 | D18: 7.7523197 | E18: 4.9572051e-13 | F18: 95.246026 | G18: 160.24566 | H18: 95.246026 | I18: 160.24566
A19: Dummy Psychology | B19: -1852.4696 | C19: 1048.7989 | D19: -1.7662773 | E19: 0.078922077 | F19: -3920.9815 | G19: 216.04236 | H19: -3920.9815 | I19: 216.04236
A20: Dummy computing | B20: 8650.6303 | C20: 1048.951 | D20: 8.2469345 | E20: 2.4202726e-14 | F20: 6581.8183 | G20: 10719.442 | H20: 6581.8183 | I20: 10719.442
A21: Dummy Bio Sci | B21: -212.72468 | C21: 1050.6874 | D21: -0.20246238 | E21: 0.83976744 | F21: -2284.9614 | G21: 1859.512 | H21: -2284.9614 | I21: 1859.512
A22: Dummy Creative arts and design | B22: -3602.0513 | C22: 1050.9014 | D22: -3.4275826 | E22: 0.00074354451 | F22: -5674.71 | G22: -1529.3926 | H22: -5674.71 | I22: -1529.3926

Sheet YAG 3 regression
A1: YAG 3 Regression — Predicted Salary vs Guardian Score and Degree Dummies
A3: Regression Statistics
A4: Multiple R | B4: 0.70655619
A5: R Square | B5: 0.49922166
A6: Adjusted R Square | B6: 0.486315
A7: Standard Error | B7: 6966.783
A8: Observations | B8: 200
A10: ANOVA
B11: df | C11: SS | D11: MS | E11: F | F11: Significance F
A12: Regression | B12: 5 | C12: 9.3867268e+09 | D12: 1.8773454e+09 | E12: 38.679389 | F12: 1.9256047e-27
A13: Residual | B13: 194 | C13: 9.4159968e+09 | D13: 48536066
A14: Total | B14: 199 | C14: 18802723550
B16: Coefficients | C16: Standard Error | D16: t Stat | E16: P-value | F16: Lower 95% | G16: Upper 95% | H16: Lower 95.0% | I16: Upper 95.0%
A17: Intercept | B17: 17007.691 | C17: 1898.7322 | D17: 8.957393 | E17: 2.7417079e-16 | F17: 13262.883 | G17: 20752.499 | H17: 13262.883 | I17: 20752.499
A18: Subject Guardian Score | B18: 205.97941 | C18: 24.476361 | D18: 8.4154427 | E18: 8.4839468e-15 | F18: 157.70548 | G18: 254.25334 | H18: 157.70548 | I18: 254.25334
A19: Dummy Psychology | B19: -4092.3923 | C19: 1557.8439 | D19: -2.6269591 | E19: 0.0093035513 | F19: -7164.8773 | G19: -1019.9072 | H19: -7164.8773 | I19: -1019.9072
A20: Dummy computing | B20: 9244.8165 | C20: 1558.0699 | D20: 5.9335056 | E20: 1.3414686e-08 | F20: 6171.8858 | G20: 12317.747 | H20: 6171.8858 | I20: 12317.747
A21: Dummy Bio Sci | B21: -2457.946 | C21: 1560.6491 | D21: -1.574951 | E21: 0.11689709 | F21: -5535.9636 | G21: 620.07165 | H21: -5535.9636 | I21: 620.07165
A22: Dummy Creative arts and design | B22: -7941.2017 | C22: 1560.9669 | D22: -5.0873606 | E22: 8.537375e-07 | F22: -11019.846 | G22: -4862.5573 | H22: -11019.846 | I22: -4862.5573

Sheet YAG 5 regression
A1: YAG 5 Regression — Predicted Salary vs Guardian Score and Degree Dummies
A3: Regression Statistics
A4: Multiple R | B4: 0.69462299
A5: R Square | B5: 0.48250109
A6: Adjusted R Square | B6: 0.46916349
A7: Standard Error | B7: 9549.4637
A8: Observations | B8: 200
A10: ANOVA
B11: df | C11: SS | D11: MS | E11: F | F11: Significance F
A12: Regression | B12: 5 | C12: 1.6494857e+10 | D12: 3.2989715e+09 | E12: 36.176004 | F12: 4.4302818e-26
A13: Residual | B13: 194 | C13: 1.7691298e+10 | D13: 91192257
A14: Total | B14: 199 | C14: 34186155200
B16: Coefficients | C16: Standard Error | D16: t Stat | E16: P-value | F16: Lower 95% | G16: Upper 95% | H16: Lower 95.0% | I16: Upper 95.0%
A17: Intercept | B17: 18969.694 | C17: 2602.6179 | D17: 7.2886972 | E17: 7.7156143e-12 | F17: 13836.635 | G17: 24102.753 | H17: 13836.635 | I17: 24102.753
A18: Subject Guardian Score | B18: 288.56225 | C18: 33.550079 | D18: 8.6009411 | E18: 2.6472042e-15 | F18: 222.39252 | G18: 354.73198 | H18: 222.39252 | I18: 354.73198
A19: Dummy Psychology | B19: -7373.2818 | C19: 2135.3578 | D19: -3.4529492 | E19: 0.00068070797 | F19: -11584.779 | G19: -3161.785 | H19: -11584.779 | I19: -3161.785
A20: Dummy computing | B20: 8976.461 | C20: 2135.6675 | D20: 4.2031173 | E20: 4.0148688e-05 | F20: 4764.3533 | G20: 13188.569 | H20: 4764.3533 | I20: 13188.569
A21: Dummy Bio Sci | B21: -5929.8576 | C21: 2139.2029 | D21: -2.771994 | E21: 0.0061141564 | F21: -10148.938 | G21: -1710.7772 | H21: -10148.938 | I21: -1710.7772
A22: Dummy Creative arts and design | B22: -12870.456 | C22: 2139.6385 | D22: -6.0152478 | E22: 8.7845771e-09 | F22: -17090.395 | G22: -8650.5162 | H22: -17090.395 | I22: -8650.5162

Sheet Dashboard Reference 
B2: Region | C2: Average of predicted ROI | E2: Country | F2: Region | G2: Average of predicted ROI | J2: County | K2: Region | L2: Country | M2: ROI | P2: YAG | Q2: Law | R2: Psychology | S2: Computing | T2: Bio Sci | U2: Creative Arts and Design | Y2: Row Labels | Z2: Mean Career After 15 Months
B3: North East | C3: 1.4390261 | E3: England | F3: North East England | G3: 1.4390261 | J3: #VALUE! | K3: #VALUE! | L3: England | M3: 1.4390261 | P3: 1 | Q3: 15455.879 | R3: -1852.4696 | S3: 8650.6303 | T3: -212.72468 | U3: -3602.0513 | Y3: Biological and Sport Sciences | Z3: 80.330552
B4: East | C4: 1.3821128 | E4: England | F4: East Midlands | G4: 1.3821128 | J4: #VALUE! | K4: #VALUE! | L4: England | M4: 1.4390261 | P4: 3 | Q4: 17007.691 | R4: -4092.3923 | S4: 9244.8165 | T4: -2457.946 | U4: -7941.2017 | Y4: Bottom 20 | Z4: 73.928571
B5: South West | C5: 1.2407627 | E5: England | F5: South West England | G5: 1.2407627 | J5: #VALUE! | K5: #VALUE! | L5: England | M5: 1.4390261 | P5: 5 | Q5: 18969.694 | R5: -7373.2818 | S5: 8976.461 | T5: -5929.8576 | U5: -12870.456 | Y5: Top 20 | Z5: 87.052632
B6: West Midlands | C6: 1.2339091 | E6: England | F6: West Midlands | G6: 1.2339091 | J6: #VALUE! | K6: #VALUE! | L6: England | M6: 1.1515758 | Y6: Computing | Z6: 86.176901
B7: Scotland | C7: 1.1901279 | E7: Scotland | F7: Scotland | G7: 1.1901279 | J7: #VALUE! | K7: #VALUE! | L7: England | M7: 1.1515758 | Y7: Bottom 20 | Z7: 78.722222
B8: North West | C8: 1.1515758 | E8: England | F8: North West England | G8: 1.1515758 | J8: #VALUE! | K8: #VALUE! | L8: England | M8: 1.1515758 | Y8: Top 20 | Z8: 93.631579
B9: Yorkshire and The Humber | C9: 1.1208933 | E9: England | F9: Yorkshire and the Humber | G9: 1.1208933 | J9: #VALUE! | K9: #VALUE! | L9: England | M9: 1.1515758 | Y9: Design and Creative Performing Arts | Z9: 70.651282
B10: South East | C10: 1.1155933 | E10: England | F10: South East England | G10: 1.1155933 | J10: #VALUE! | K10: #VALUE! | L10: England | M10: 1.1515758 | Y10: Bottom 20 | Z10: 64.769231
B11: East Midlands | C11: 1.0796802 | E11: England | F11: East Midlands | G11: 1.0796802 | J11: #VALUE! | K11: #VALUE! | L11: England | M11: 1.1208933 | Y11: Top 20 | Z11: 76.533333
B12: Wales | C12: 1.067768 | E12: Wales | F12: Wales | G12: 1.067768 | J12: #VALUE! | K12: #VALUE! | L12: England | M12: 1.1208933 | Y12: Law | Z12: 82.613003
B13: Northern Ireland | C13: 1.066194 | E13: England | F13: Northern Ireland | G13: 1.066194 | J13: #VALUE! | K13: #VALUE! | L13: England | M13: 1.1208933 | Y13: Bottom 20 | Z13: 76.647059
B14: London | C14: 1.0255028 | E14: England | F14: London | G14: 1.066194 | J14: #VALUE! | K14: #VALUE! | L14: England | M14: 1.1208933 | Y14: Top 20 | Z14: 88.578947
B15: Grand Total | C15: 1.153033 | J15: #VALUE! | K15: #VALUE! | L15: England | M15: 1.0796802 | Y15: Psychology | Z15: 73.625731
J16: #VALUE! | K16: #VALUE! | L16: England | M16: 1.0796802 | Y16: Bottom 20 | Z16: 65.777778
J17: #VALUE! | K17: #VALUE! | L17: England | M17: 1.0796802 | Y17: Top 20 | Z17: 81.473684
J18: #VALUE! | K18: #VALUE! | L18: England | M18: 1.0796802 | Y18: Grand Total | Z18: 78.687708
J19: #VALUE! | K19: #VALUE! | L19: England | M19: 1.0796802
J20: #VALUE! | K20: #VALUE! | L20: England | M20: 1.0796802
J21: #VALUE! | K21: #VALUE! | L21: England | M21: 1.2339091
J22: #VALUE! | K22: #VALUE! | L22: England | M22: 1.2339091
J23: #VALUE! | K23: #VALUE! | L23: England | M23: 1.2339091
J24: #VALUE! | K24: #VALUE! | L24: England | M24: 1.2339091
J25: #VALUE! | K25: #VALUE! | L25: England | M25: 1.2339091
J26: #VALUE! | K26: #VALUE! | L26: England | M26: 1.2339091
J27: #VALUE! | K27: #VALUE! | L27: England | M27: 1.1155933
J28: #VALUE! | K28: #VALUE! | L28: England | M28: 1.1155933
J29: #VALUE! | K29: #VALUE! | L29: England | M29: 1.1155933
J30: #VALUE! | K30: #VALUE! | L30: England | M30: 1.1155933
J31: #VALUE! | K31: #VALUE! | L31: England | M31: 1.1155933
J32: #VALUE! | K32: #VALUE! | L32: England | M32: 1.1155933 | P32: R Squared Value | Q32: YAG
J33: #VALUE! | K33: #VALUE! | L33: England | M33: 1.1155933 | P33: 0.52023386 | Q33: 1
J34: #VALUE! | K34: #VALUE! | L34: England | M34: 1.1155933 | P34: 0.49922166 | Q34: 3
J35: #VALUE! | K35: #VALUE! | L35: England | M35: 1.1155933 | P35: 0.48250109 | Q35: 5
J36: #VALUE! | K36: #VALUE! | L36: England | M36: 1.2407627
J37: #VALUE! | K37: #VALUE! | L37: England | M37: 1.2407627
J38: #VALUE! | K38: #VALUE! | L38: England | M38: 1.2407627
J39: #VALUE! | K39: #VALUE! | L39: England | M39: 1.2407627
J40: #VALUE! | K40: #VALUE! | L40: England | M40: 1.2407627
J41: #VALUE! | K41: #VALUE! | L41: England | M41: 1.2407627
...

Sheet Provider level data
A1: tax_year | B1: academic_year | C1: YAG | D1: home_region_code | E1: home_region_name | F1: ukprn | G1: provider_name | H1: provider_type | I1: provider_country_code | J1: provider_country_name | K1: provider_region_code | L1: provider_region_name | M1: current_region_code | N1: current_region_name | O1: cah2_code | P1: cah2_subject_name | Q1: grads | R1: grads_uk | S1: grads_matched | T1: activity_not_captured | U1: no_sust_dest | V1: sust_emp_only | W1: sust_emp_with_or_without_fs | X1: sust_emp_fs_or_both | Y1: fs_with_or_without_sust_emp | Z1: fs_only | AA1: grads_earnings_include | AB1: earnings_lower | AC1: earnings_LQ | AD1: earnings_median | AE1: earnings_UQ | AF1: earnings_upper | AG1: earnings_adjusted_lower | AH1: earnings_adjusted_LQ | AI1: earnings_adjusted_median | AJ1: earnings_adjusted_UQ | AK1: earnings_adjusted_upper | AL1: characteristic_type | AM1: characteristic_value
A2: 2022/2023 | B2: 2016/2017 | C2: 5 | D2: Total | E2: Total | F2: 10000093 | G2: Accrington and Rossendale College | H2: FEC | I2: E92000001 | J2: England | K2: E12000002 | L2: North West | M2: Total | N2: Total | O2: CAH11-01 | P2: Computing | Q2: 5 | R2: 5 | S2: 5 | T2: c | U2: c | V2: c | W2: c | X2: c | Y2: c | Z2: c | AA2: low | AB2: c | AC2: c | AD2: c | AE2: c | AF2: c | AG2: c | AH2: c | AI2: c | AJ2: c | AK2: c | AL2: All graduates | AM2: All graduates
A3: 2022/2023 | B3: 2016/2017 | C3: 5 | D3: Total | E3: Total | F3: 10000291 | G3: Anglia Ruskin University | H3: HEI | I3: E92000001 | J3: England | K3: E12000006 | L3: East of England | M3: Total | N3: Total | O3: CAH03-01 | P3: Biosciences | Q3: 170 | R3: 165 | S3: 165 | T3: 5.5 | U3: 5.5 | V3: 78.8 | W3: 86.7 | X3: 89.1 | Y3: 10.3 | Z3: 2.4 | AA3: 125 | AB3: 700 | AC3: 21900 | AD3: 27700 | AE3: 32800 | AF3: 140900 | AG3: c | AH3: c | AI3: c | AJ3: c | AK3: c | AL3: All graduates | AM3: All graduates
A4: 2022/2023 | B4: 2016/2017 | C4: 5 | D4: Total | E4: Total | F4: 10000291 | G4: Anglia Ruskin University | H4: HEI | I4: E92000001 | J4: England | K4: E12000006 | L4: East of England | M4: Total | N4: Total | O4: CAH04-01 | P4: Psychology | Q4: 140 | R4: 135 | S4: 135 | T4: 2.9 | U4: 6.6 | V4: 62.8 | W4: 84.7 | X4: 90.5 | Y4: 27.7 | Z4: 5.8 | AA4: 85 | AB4: 4400 | AC4: 22300 | AD4: 26300 | AE4: 31400 | AF4: 61700 | AG4: c | AH4: c | AI4: c | AJ4: c | AK4: c | AL4: All graduates | AM4: All graduates
A5: 2022/2023 | B5: 2016/2017 | C5: 5 | D5: Total | E5: Total | F5: 10000291 | G5: Anglia Ruskin University | H5: HEI | I5: E92000001 | J5: England | K5: E12000006 | L5: East of England | M5: Total | N5: Total | O5: CAH11-01 | P5: Computing | Q5: 145 | R5: 140 | S5: 140 | T5: 8.5 | U5: 7.8 | V5: 82.3 | W5: 83.7 | X5: 83.7 | Y5: 1.4 | Z5: z | AA5: 115 | AB5: 4700 | AC5: 24800 | AD5: 33200 | AE5: 43400 | AF5: 292700 | AG5: c | AH5: c | AI5: c | AJ5: c | AK5: c | AL5: All graduates | AM5: All graduates
A6: 2022/2023 | B6: 2016/2017 | C6: 5 | D6: Total | E6: Total | F6: 10000291 | G6: Anglia Ruskin University | H6: HEI | I6: E92000001 | J6: England | K6: E12000006 | L6: East of England | M6: Total | N6: Total | O6: CAH16-01 | P6: Law | Q6: 150 | R6: 150 | S6: 145 | T6: 4.1 | U6: 9.6 | V6: 77.4 | W6: 83.6 | X6: 86.3 | Y6: 8.9 | Z6: 2.7 | AA6: 115 | AB6: 6600 | AC6: 23000 | AD6: 29200 | AE6: 36900 | AF6: 96700 | AG6: c | AH6: c | AI6: c | AJ6: c | AK6: c | AL6: All graduates | AM6: All graduates
A7: 2022/2023 | B7: 2016/2017 | C7: 5 | D7: Total | E7: Total | F7: 10000291 | G7: Anglia Ruskin University | H7: HEI | I7: E92000001 | J7: England | K7: E12000006 | L7: East of England | M7: Total | N7: Total | O7: CAH25-01 | P7: Creative arts and design | Q7: 140 | R7: 130 | S7: 130 | T7: 4.2 | U7: 10.8 | V7: 79.6 | W7: 82.7 | X7: 85 | Y7: 5.4 | Z7: 2.3 | AA7: 100 | AB7: 300 | AC7: 19000 | AD7: 24100 | AE7: 29200 | AF7: 51100 | AG7: c | AH7: c | AI7: c | AJ7: c | AK7: c | AL7: All graduates | AM7: All graduates
A8: 2022/2023 | B8: 2016/2017 | C8: 5 | D8: Total | E8: Total | F8: 10000385 | G8: Arts University Bournemouth | H8: HEI | I8: E92000001 | J8: England | K8: E12000009 | L8: South West | M8: Total | N8: Total | O8: CAH25-01 | P8: Creative arts and design | Q8: 545 | R8: 535 | S8: 530 | T8: 3.4 | U8: 6 | V8: 86.6 | W8: 89.6 | X8: 90.6 | Y8: 4 | Z8: 0.9 | AA8: 445 | AB8: 400 | AC8: 20800 | AD8: 27000 | AE8: 34300 | AF8: 94500 | AG8: c | AH8: c | AI8: c | AJ8: c | AK8: c | AL8: All graduates | AM8: All graduates
A9: 2022/2023 | B9: 2016/2017 | C9: 5 | D9: Total | E9: Total | F9: 10000415 | G9: Askham Bryan College | H9: FEC | I9: E92000001 | J9: England | K9: E12000003 | L9: Yorkshire and The Humber | M9: Total | N9: Total | O9: CAH03-01 | P9: Biosciences | Q9: 5 | R9: 5 | S9: 5 | T9: c | U9: c | V9: c | W9: c | X9: c | Y9: c | Z9: c | AA9: 5 | AB9: c | AC9: c | AD9: c | AE9: c | AF9: c | AG9: c | AH9: c | AI9: c | AJ9: c | AK9: c | AL9: All graduates | AM9: All graduates
A10: 2022/2023 | B10: 2016/2017 | C10: 5 | D10: Total | E10: Total | F10: 10000528 | G10: Barking and Dagenham College | H10: FEC | I10: E92000001 | J10: England | K10: E12000007 | L10: London | M10: Total | N10: Total | O10: CAH25-01 | P10: Creative arts and design | Q10: 10 | R10: 10 | S10: 10 | T10: c | U10: c | V10: c | W10: c | X10: c | Y10: c | Z10: c | AA10: 5 | AB10: c | AC10: c | AD10: c | AE10: c | AF10: c | AG10: c | AH10: c | AI10: c | AJ10: c | AK10: c | AL10: All graduates | AM10: All graduates
A11: 2022/2023 | B11: 2016/2017 | C11: 5 | D11: Total | E11: Total | F11: 10000533 | G11: Barnet and Southgate College | H11: FEC | I11: E92000001 | J11: England | K11: E12000007 | L11: London | M11: Total | N11: Total | O11: CAH11-01 | P11: Computing | Q11: 5 | R11: 5 | S11: 5 | T11: c | U11: c | V11: c | W11: c | X11: c | Y11: c | Z11: c | AA11: 5 | AB11: c | AC11: c | AD11: c | AE11: c | AF11: c | AG11: c | AH11: c | AI11: c | AJ11: c | AK11: c | AL11: All graduates | AM11: All graduates
A12: 2022/2023 | B12: 2016/2017 | C12: 5 | D12: Total | E12: Total | F12: 10000536 | G12: Barnsley College | H12: FEC | I12: E92000001 | J12: England | K12: E12000003 | L12: Yorkshire and The Humber | M12: Total | N12: Total | O12: CAH25-01 | P12: Creative arts and design | Q12: 5 | R12: 5 | S12: 5 | T12: c | U12: c | V12: c | W12: c | X12: c | Y12: c | Z12: c | AA12: 5 | AB12: c | AC12: c | AD12: c | AE12: c | AF12: c | AG12: c | AH12: c | AI12: c | AJ12: c | AK12: c | AL12: All graduates | AM12: All graduates
A13: 2022/2023 | B13: 2016/2017 | C13: 5 | D13: Total | E13: Total | F13: 10000560 | G13: Basingstoke College of Technology | H13: FEC | I13: E92000001 | J13: England | K13: E12000008 | L13: South East | M13: Total | N13: Total | O13: CAH25-01 | P13: Creative arts and design | Q13: 10 | R13: 10 | S13: 10 | T13: c | U13: c | V13: c | W13: c | X13: c | Y13: c | Z13: c | AA13: 5 | AB13: c | AC13: c | AD13: c | AE13: c | AF13: c | AG13: c | AH13: c | AI13: c | AJ13: c | AK13: c | AL13: All graduates | AM13: All graduates
A14: 2022/2023 | B14: 2016/2017 | C14: 5 | D14: Total | E14: Total | F14: 10000571 | G14: Bath Spa University | H14: HEI | I14: E92000001 | J14: England | K14: E12000009 | L14: South West | M14: Total | N14: Total | O14: CAH03-01 | P14: Biosciences | Q14: 30 | R14: 30 | S14: 30 | T14: 3.4 | U14: 6.9 | V14: 69 | W14: 86.2 | X14: 89.7 | Y14: 20.7 | Z14: 3.4 | AA14: 20 | AB14: 20800 | AC14: 29900 | AD14: 34300 | AE14: 39800 | AF14: 75600 | AG14: c | AH14: c | AI14: c | AJ14: c | AK14: c | AL14: All graduates | AM14: All graduates
A15: 2022/2023 | B15: 2016/2017 | C15: 5 | D15: Total | E15: Total | F15: 10000571 | G15: Bath Spa University | H15: HEI | I15: E92000001 | J15: England | K15: E12000009 | L15: South West | M15: Total | N15: Total | O15: CAH04-01 | P15: Psychology | Q15: 65 | R15: 65 | S15: 65 | T15: 6.9 | U15: 7.1 | V15: 66.4 | W15: 82.3 | X15: 86 | Y15: 19.6 | Z15: 3.7 | AA15: 40 | AB15: 2900 | AC15: 21900 | AD15: 29600 | AE15: 36100 | AF15: 61900 | AG15: c | AH15: c | AI15: c | AJ15: c | AK15: c | AL15: All graduates | AM15: All graduates
A16: 2022/2023 | B16: 2016/2017 | C16: 5 | D16: Total | E16: Total | F16: 10000571 | G16: Bath Spa University | H16: HEI | I16: E92000001 | J16: England | K16: E12000009 | L16: South West | M16: Total | N16: Total | O16: CAH25-01 | P16: Creative arts and design | Q16: 280 | R16: 275 | S16: 275 | T16: 4 | U16: 9.8 | V16: 81.5 | W16: 85.5 | X16: 86.2 | Y16: 4.7 | Z16: 0.7 | AA16: 215 | AB16: 2600 | AC16: 20400 | AD16: 26600 | AE16: 31500 | AF16: 51800 | AG16: c | AH16: c | AI16: c | AJ16: c | AK16: c | AL16: All graduates | AM16: All graduates
A17: 2022/2023 | B17: 2016/2017 | C17: 5 | D17: Total | E17: Total | F17: 10000721 | G17: Bishop Burton College | H17: FEC | I17: E92000001 | J17: England | K17: E12000003 | L17: Yorkshire and The Humber | M17: Total | N17: Total | O17: CAH03-01 | P17: Biosciences | Q17: 25 | R17: 25 | S17: 25 | T17: z | U17: 7.4 | V17: 70.4 | W17: 92.6 | X17: 92.6 | Y17: 22.2 | Z17: z | AA17: 15 | AB17: 7300 | AC17: 13100 | AD17: 19000 | AE17: 20800 | AF17: 46400 | AG17: c | AH17: c | AI17: c | AJ17: c | AK17: c | AL17: All graduates | AM17: All graduates
A18: 2022/2023 | B18: 2016/2017 | C18: 5 | D18: Total | E18: Total | F18: 10000721 | G18: Bishop Burton College | H18: FEC | I18: E92000001 | J18: England | K18: E12000003 | L18: Yorkshire and The Humber | M18: Total | N18: Total | O18: CAH25-01 | P18: Creative arts and design | Q18: 5 | R18: 5 | S18: 5 | T18: c | U18: c | V18: c | W18: c | X18: c | Y18: c | Z18: c | AA18: 5 | AB18: c | AC18: c | AD18: c | AE18: c | AF18: c | AG18: c | AH18: c | AI18: c | AJ18: c | AK18: c | AL18: All graduates | AM18: All graduates
A19: 2022/2023 | B19: 2016/2017 | C19: 5 | D19: Total | E19: Total | F19: 10000747 | G19: Blackburn College | H19: FEC | I19: E92000001 | J19: England | K19: E12000002 | L19: North West | M19: Total | N19: Total | O19: CAH04-01 | P19: Psychology | Q19: 20 | R19: 20 | S19: 20 | T19: 5 | U19: z | V19: 80 | W19: 90 | X19: 95 | Y19: 15 | Z19: 5 | AA19: 15 | AB19: 700 | AC19: 17500 | AD19: 23000 | AE19: 32100 | AF19: 41200 | AG19: c | AH19: c | AI19: c | AJ19: c | AK19: c | AL19: All graduates | AM19: All graduates
A20: 2022/2023 | B20: 2016/2017 | C20: 5 | D20: Total | E20: Total | F20: 10000747 | G20: Blackburn College | H20: FEC | I20: E92000001 | J20: England | K20: E12000002 | L20: North West | M20: Total | N20: Total | O20: CAH11-01 | P20: Computing | Q20: 10 | R20: 10 | S20: 10 | T20: c | U20: c | V20: c | W20: c | X20: c | Y20: c | Z20: c | AA20: 5 | AB20: c | AC20: c | AD20: c | AE20: c | AF20: c | AG20: c | AH20: c | AI20: c | AJ20: c | AK20: c | AL20: All graduates | AM20: All graduates
A21: 2022/2023 | B21: 2016/2017 | C21: 5 | D21: Total | E21: Total | F21: 10000747 | G21: Blackburn College | H21: FEC | I21: E92000001 | J21: England | K21: E12000002 | L21: North West | M21: Total | N21: Total | O21: CAH16-01 | P21: Law | Q21: 30 | R21: 30 | S21: 30 | T21: 10.7 | U21: 10.7 | V21: 75 | W21: 78.6 | X21: 78.6 | Y21: 3.6 | Z21: z | AA21: 20 | AB21: 3600 | AC21: 10600 | AD21: 23000 | AE21: 26300 | AF21: 36100 | AG21: c | AH21: c | AI21: c | AJ21: c | AK21: c | AL21: All graduates | AM21: All graduates
A22: 2022/2023 | B22: 2016/2017 | C22: 5 | D22: Total | E22: Total | F22: 10000747 | G22: Blackburn College | H22: FEC | I22: E92000001 | J22: England | K22: E12000002 | L22: North West | M22: Total | N22: Total | O22: CAH25-01 | P22: Creative arts and design | Q22: 50 | R22: 50 | S22: 50 | T22: 4.2 | U22: 20.8 | V22: 70.8 | W22: 75 | X22: 75 | Y22: 4.2 | Z22: z | AA22: 30 | AB22: 6200 | AC22: 15800 | AD22: 20100 | AE22: 23000 | AF22: 38700 | AG22: c | AH22: c | AI22: c | AJ22: c | AK22: c | AL22: All graduates | AM22: All graduates
A23: 2022/2023 | B23: 2016/2017 | C23: 5 | D23: Total | E23: Total | F23: 10000754 | G23: Blackpool and The Fylde College | H23: FEC | I23: E92000001 | J23: England | K23: E12000002 | L23: North West | M23: Total | N23: Total | O23: CAH03-01 | P23: Biosciences | Q23: 25 | R23: 25 | S23: 25 | T23: 4.2 | U23: 4.2 | V23: 70.8 | W23: 91.7 | X23: 91.7 | Y23: 20.8 | Z23: z | AA23: 15 | AB23: 11000 | AC23: 18200 | AD23: 22600 | AE23: 25600 | AF23: 39100 | AG23: c | AH23: c | AI23: c | AJ23: c | AK23: c | AL23: All graduates | AM23: All graduates
A24: 2022/2023 | B24: 2016/2017 | C24: 5 | D24: Total | E24: Total | F24: 10000754 | G24: Blackpool and The Fylde College | H24: FEC | I24: E92000001 | J24: England | K24: E12000002 | L24: North West | M24: Total | N24: Total | O24: CAH11-01 | P24: Computing | Q24: 30 | R24: 30 | S24: 30 | T24: 3.6 | U24: 7.1 | V24: 82.1 | W24: 89.3 | X24: 89.3 | Y24: 7.1 | Z24: z | AA24: 25 | AB24: 10200 | AC24: 20100 | AD24: 27000 | AE24: 35800 | AF24: 55800 | AG24: c | AH24: c | AI24: c | AJ24: c | AK24: c | AL24: All graduates | AM24: All graduates
A25: 2022/2023 | B25: 2016/2017 | C25: 5 | D25: Total | E25: Total | F25: 10000754 | G25: Blackpool and The Fylde College | H25: FEC | I25: E92000001 | J25: England | K25: E12000002 | L25: North West | M25: Total | N25: Total | O25: CAH25-01 | P25: Creative arts and design | Q25: 65 | R25: 65 | S25: 65 | T25: 6.3 | U25: 12.7 | V25: 77.8 | W25: 81 | X25: 81 | Y25: 3.2 | Z25: z | AA25: 45 | AB25: 600 | AC25: 13900 | AD25: 20800 | AE25: 25900 | AF25: 43800 | AG25: c | AH25: c | AI25: c | AJ25: c | AK25: c | AL25: All graduates | AM25: All graduates
A26: 2022/2023 | B26: 2016/2017 | C26: 5 | D26: Total | E26: Total | F26: 10000824 | G26: Bournemouth University | H26: HEI | I26: E92000001 | J26: England | K26: E12000009 | L26: South West | M26: Total | N26: Total | O26: CAH03-01 | P26: Biosciences | Q26: 85 | R26: 85 | S26: 85 | T26: 6 | U26: 1.2 | V26: 78.6 | W26: 89.3 | X26: 92.9 | Y26: 14.3 | Z26: 3.6 | AA26: 60 | AB26: 5100 | AC26: 23400 | AD26: 28100 | AE26: 31400 | AF26: 66400 | AG26: c | AH26: c | AI26: c | AJ26: c | AK26: c | AL26: All graduates | AM26: All graduates
A27: 2022/2023 | B27: 2016/2017 | C27: 5 | D27: Total | E27: Total | F27: 10000824 | G27: Bournemouth University | H27: HEI | I27: E92000001 | J27: England | K27: E12000009 | L27: South West | M27: Total | N27: Total | O27: CAH04-01 | P27: Psychology | Q27: 195 | R27: 195 | S27: 195 | T27: 2.4 | U27: 2.2 | V27: 78.7 | W27: 92.8 | X27: 95.4 | Y27: 16.7 | Z27: 2.6 | AA27: 150 | AB27: 1100 | AC27: 24100 | AD27: 30300 | AE27: 36100 | AF27: 120100 | AG27: c | AH27: c | AI27: c | AJ27: c | AK27: c | AL27: All graduates | AM27: All graduates
A28: 2022/2023 | B28: 2016/2017 | C28: 5 | D28: Total | E28: Total | F28: 10000824 | G28: Bournemouth University | H28: HEI | I28: E92000001 | J28: England | K28: E12000009 | L28: South West | M28: Total | N28: Total | O28: CAH11-01 | P28: Computing | Q28: 270 | R28: 260 | S28: 255 | T28: 2.5 | U28: 4.7 | V28: 89.3 | W28: 91.6 | X28: 92.8 | Y28: 3.5 | Z28: 1.2 | AA28: 220 | AB28: 2500 | AC28: 28800 | AD28: 41200 | AE28: 55100 | AF28: 147500 | AG28: c | AH28: c | AI28: c | AJ28: c | AK28: c | AL28: All graduates | AM28: All graduates
A29: 2022/2023 | B29: 2016/2017 | C29: 5 | D29: Total | E29: Total | F29: 10000824 | G29: Bournemouth University | H29: HEI | I29: E92000001 | J29: England | K29: E12000009 | L29: South West | M29: Total | N29: Total | O29: CAH16-01 | P29: Law | Q29: 35 | R29: 35 | S29: 35 | T29: 2.7 | U29: 2.7 | V29: 87.7 | W29: 93.2 | X29: 94.5 | Y29: 6.8 | Z29: 1.4 | AA29: 30 | AB29: 9500 | AC29: 26600 | AD29: 34300 | AE29: 45200 | AF29: 92300 | AG29: c | AH29: c | AI29: c | AJ29: c | AK29: c | AL29: All graduates | AM29: All graduates
A30: 2022/2023 | B30: 2016/2017 | C30: 5 | D30: Total | E30: Total | F30: 10000824 | G30: Bournemouth University | H30: HEI | I30: E92000001 | J30: England | K30: E12000009 | L30: South West | M30: Total | N30: Total | O30: CAH25-01 | P30: Creative arts and design | Q30: 175 | R30: 165 | S30: 160 | T30: 6.8 | U30: 3.7 | V30: 86.4 | W30: 88.3 | X30: 89.5 | Y30: 3.1 | Z30: 1.2 | AA30: 140 | AB30: 3600 | AC30: 28500 | AD30: 36100 | AE30: 45300 | AF30: 140500 | AG30: c | AH30: c | AI30: c | AJ30: c | AK30: c | AL30: All graduates | AM30: All graduates
A31: 2022/2023 | B31: 2016/2017 | C31: 5 | D31: Total | E31: Total | F31: 10000840 | G31: Bradford College | H31: FEC | I31: E92000001 | J31: England | K31: E12000003 | L31: Yorkshire and The Humber | M31: Total | N31: Total | O31: CAH11-01 | P31: Computing | Q31: 15 | R31: 15 | S31: 15 | T31: 0.8 | U31: 1.6 | V31: 97.6 | W31: 97.6 | X31: 97.6 | Y31: z | Z31: z | AA31: 10 | AB31: 15300 | AC31: 19300 | AD31: 24800 | AE31: 28500 | AF31: 45600 | AG31: c | AH31: c | AI31: c | AJ31: c | AK31: c | AL31: All graduates | AM31: All graduates
A32: 2022/2023 | B32: 2016/2017 | C32: 5 | D32: Total | E32: Total | F32: 10000840 | G32: Bradford College | H32: FEC | I32: E92000001 | J32: England | K32: E12000003 | L32: Yorkshire and The Humber | M32: Total | N32: Total | O32: CAH16-01 | P32: Law | Q32: 30 | R32: 30 | S32: 25 | T32: 15.4 | U32: 19.2 | V32: 57.7 | W32: 61.5 | X32: 65.4 | Y32: 7.7 | Z32: 3.8 | AA32: 15 | AB32: 11000 | AC32: 18200 | AD32: 22600 | AE32: 31000 | AF32: 38700 | AG32: c | AH32: c | AI32: c | AJ32: c | AK32: c | AL32: All graduates | AM32: All graduates
A33: 2022/2023 | B33: 2016/2017 | C33: 5 | D33: Total | E33: Total | F33: 10000840 | G33: Bradford College | H33: FEC | I33: E92000001 | J33: England | K33: E12000003 | L33: Yorkshire and The Humber | M33: Total | N33: Total | O33: CAH25-01 | P33: Creative arts and design | Q33: 65 | R33: 65 | S33: 65 | T33: 13.2 | U33: 19 | V33: 63.4 | W33: 66.3 | X33: 67.8 | Y33: 4.5 | Z33: 1.5 | AA33: 40 | AB33: 6200 | AC33: 15200 | AD33: 21300 | AE33: 27000 | AF33: 44200 | AG33: c | AH33: c | AI33: c | AJ33: c | AK33: c | AL33: All graduates | AM33: All graduates
A34: 2022/2023 | B34: 2016/2017 | C34: 5 | D34: Total | E34: Total | F34: 10000878 | G34: Bridgwater and Taunton College | H34: FEC | I34: E92000001 | J34: England | K34: E12000009 | L34: South West | M34: Total | N34: Total | O34: CAH11-01 | P34: Computing | Q34: 25 | R34: 25 | S34: 25 | T34: 4.3 | U34: z | V34: 95.7 | W34: 95.7 | X34: 95.7 | Y34: z | Z34: z | AA34: 20 | AB34: 14200 | AC34: 24800 | AD34: 29600 | AE34: 36100 | AF34: 76300 | AG34: c | AH34: c | AI34: c | AJ34: c | AK34: c | AL34: All graduates | AM34: All graduates
A35: 2022/2023 | B35: 2016/2017 | C35: 5 | D35: Total | E35: Total | F35: 10000878 | G35: Bridgwater and Taunton College | H35: FEC | I35: E92000001 | J35: England | K35: E12000009 | L35: South West | M35: Total | N35: Total | O35: CAH25-01 | P35: Creative arts and design | Q35: 10 | R35: 10 | S35: 10 | T35: c | U35: c | V35: c | W35: c | X35: c | Y35: c | Z35: c | AA35: 5 | AB35: c | AC35: c | AD35: c | AE35: c | AF35: c | AG35: c | AH35: c | AI35: c | AJ35: c | AK35: c | AL35: All graduates | AM35: All graduates
A36: 2022/2023 | B36: 2016/2017 | C36: 5 | D36: Total | E36: Total | F36: 10000886 | G36: University of Brighton | H36: HEI | I36: E92000001 | J36: England | K36: E12000008 | L36: South East | M36: Total | N36: Total | O36: CAH03-01 | P36: Biosciences | Q36: 50 | R36: 45 | S36: 45 | T36: 10.9 | U36: 2.2 | V36: 65.2 | W36: 78.3 | X36: 87 | Y36: 21.7 | Z36: 8.7 | AA36: 30 | AB36: 9100 | AC36: 25200 | AD36: 28500 | AE36: 36100 | AF36: 75200 | AG36: c | AH36: c | AI36: c | AJ36: c | AK36: c | AL36: All graduates | AM36: All graduates
A37: 2022/2023 | B37: 2016/2017 | C37: 5 | D37: Total | E37: Total | F37: 10000886 | G37: University of Brighton | H37: HEI | I37: E92000001 | J37: England | K37: E12000008 | L37: South East | M37: Total | N37: Total | O37: CAH04-01 | P37: Psychology | Q37: 50 | R37: 45 | S37: 45 | T37: 3.2 | U37: 5.4 | V37: 72 | W37: 91.4 | X37: 91.4 | Y37: 19.4 | Z37: z | AA37: 35 | AB37: 8800 | AC37: 23000 | AD37: 27900 | AE37: 34700 | AF37: 81400 | AG37: c | AH37: c | AI37: c | AJ37: c | AK37: c | AL37: All graduates | AM37: All graduates
